2019-12-08 18:23:29,113 ERROR: Exception on /index [GET] [in /Users/ethanhellman/Desktop/microblog/venv/lib/python3.8/site-packages/flask/app.py:1890]
Traceback (most recent call last):
  File "/Users/ethanhellman/Desktop/microblog/venv/lib/python3.8/site-packages/flask/app.py", line 2446, in wsgi_app
    response = self.full_dispatch_request()
  File "/Users/ethanhellman/Desktop/microblog/venv/lib/python3.8/site-packages/flask/app.py", line 1951, in full_dispatch_request
    rv = self.handle_user_exception(e)
  File "/Users/ethanhellman/Desktop/microblog/venv/lib/python3.8/site-packages/flask/app.py", line 1820, in handle_user_exception
    reraise(exc_type, exc_value, tb)
  File "/Users/ethanhellman/Desktop/microblog/venv/lib/python3.8/site-packages/flask/_compat.py", line 39, in reraise
    raise value
  File "/Users/ethanhellman/Desktop/microblog/venv/lib/python3.8/site-packages/flask/app.py", line 1949, in full_dispatch_request
    rv = self.dispatch_request()
  File "/Users/ethanhellman/Desktop/microblog/venv/lib/python3.8/site-packages/flask/app.py", line 1935, in dispatch_request
    return self.view_functions[rule.endpoint](**req.view_args)
  File "/Users/ethanhellman/Desktop/microblog/venv/lib/python3.8/site-packages/flask_login/utils.py", line 261, in decorated_view
    return func(*args, **kwargs)
  File "/Users/ethanhellman/Desktop/microblog/app/routes.py", line 25, in index
    posts = Post.query.filter_by(user_id=self.id)
NameError: name 'self' is not defined
2019-12-08 18:23:31,372 ERROR: Exception on /index [GET] [in /Users/ethanhellman/Desktop/microblog/venv/lib/python3.8/site-packages/flask/app.py:1890]
Traceback (most recent call last):
  File "/Users/ethanhellman/Desktop/microblog/venv/lib/python3.8/site-packages/flask/app.py", line 2446, in wsgi_app
    response = self.full_dispatch_request()
  File "/Users/ethanhellman/Desktop/microblog/venv/lib/python3.8/site-packages/flask/app.py", line 1951, in full_dispatch_request
    rv = self.handle_user_exception(e)
  File "/Users/ethanhellman/Desktop/microblog/venv/lib/python3.8/site-packages/flask/app.py", line 1820, in handle_user_exception
    reraise(exc_type, exc_value, tb)
  File "/Users/ethanhellman/Desktop/microblog/venv/lib/python3.8/site-packages/flask/_compat.py", line 39, in reraise
    raise value
  File "/Users/ethanhellman/Desktop/microblog/venv/lib/python3.8/site-packages/flask/app.py", line 1949, in full_dispatch_request
    rv = self.dispatch_request()
  File "/Users/ethanhellman/Desktop/microblog/venv/lib/python3.8/site-packages/flask/app.py", line 1935, in dispatch_request
    return self.view_functions[rule.endpoint](**req.view_args)
  File "/Users/ethanhellman/Desktop/microblog/venv/lib/python3.8/site-packages/flask_login/utils.py", line 261, in decorated_view
    return func(*args, **kwargs)
  File "/Users/ethanhellman/Desktop/microblog/app/routes.py", line 25, in index
    posts = Post.query.filter_by(user_id=self.id)
NameError: name 'self' is not defined
2019-12-08 18:23:32,315 ERROR: Exception on /index [GET] [in /Users/ethanhellman/Desktop/microblog/venv/lib/python3.8/site-packages/flask/app.py:1890]
Traceback (most recent call last):
  File "/Users/ethanhellman/Desktop/microblog/venv/lib/python3.8/site-packages/flask/app.py", line 2446, in wsgi_app
    response = self.full_dispatch_request()
  File "/Users/ethanhellman/Desktop/microblog/venv/lib/python3.8/site-packages/flask/app.py", line 1951, in full_dispatch_request
    rv = self.handle_user_exception(e)
  File "/Users/ethanhellman/Desktop/microblog/venv/lib/python3.8/site-packages/flask/app.py", line 1820, in handle_user_exception
    reraise(exc_type, exc_value, tb)
  File "/Users/ethanhellman/Desktop/microblog/venv/lib/python3.8/site-packages/flask/_compat.py", line 39, in reraise
    raise value
  File "/Users/ethanhellman/Desktop/microblog/venv/lib/python3.8/site-packages/flask/app.py", line 1949, in full_dispatch_request
    rv = self.dispatch_request()
  File "/Users/ethanhellman/Desktop/microblog/venv/lib/python3.8/site-packages/flask/app.py", line 1935, in dispatch_request
    return self.view_functions[rule.endpoint](**req.view_args)
  File "/Users/ethanhellman/Desktop/microblog/venv/lib/python3.8/site-packages/flask_login/utils.py", line 261, in decorated_view
    return func(*args, **kwargs)
  File "/Users/ethanhellman/Desktop/microblog/app/routes.py", line 25, in index
    posts = Post.query.filter_by(user_id=self.id)
NameError: name 'self' is not defined
2019-12-08 18:23:33,436 ERROR: Exception on /user/mack [GET] [in /Users/ethanhellman/Desktop/microblog/venv/lib/python3.8/site-packages/flask/app.py:1890]
Traceback (most recent call last):
  File "/Users/ethanhellman/Desktop/microblog/venv/lib/python3.8/site-packages/flask/app.py", line 2446, in wsgi_app
    response = self.full_dispatch_request()
  File "/Users/ethanhellman/Desktop/microblog/venv/lib/python3.8/site-packages/flask/app.py", line 1951, in full_dispatch_request
    rv = self.handle_user_exception(e)
  File "/Users/ethanhellman/Desktop/microblog/venv/lib/python3.8/site-packages/flask/app.py", line 1820, in handle_user_exception
    reraise(exc_type, exc_value, tb)
  File "/Users/ethanhellman/Desktop/microblog/venv/lib/python3.8/site-packages/flask/_compat.py", line 39, in reraise
    raise value
  File "/Users/ethanhellman/Desktop/microblog/venv/lib/python3.8/site-packages/flask/app.py", line 1949, in full_dispatch_request
    rv = self.dispatch_request()
  File "/Users/ethanhellman/Desktop/microblog/venv/lib/python3.8/site-packages/flask/app.py", line 1935, in dispatch_request
    return self.view_functions[rule.endpoint](**req.view_args)
  File "/Users/ethanhellman/Desktop/microblog/venv/lib/python3.8/site-packages/flask_login/utils.py", line 261, in decorated_view
    return func(*args, **kwargs)
  File "/Users/ethanhellman/Desktop/microblog/app/routes.py", line 87, in user
    posts = Post.query.filter_by(author=username).filter_by.datetime
  File "/Users/ethanhellman/Desktop/microblog/venv/lib/python3.8/site-packages/sqlalchemy/orm/query.py", line 1823, in filter_by
    clauses = [
  File "/Users/ethanhellman/Desktop/microblog/venv/lib/python3.8/site-packages/sqlalchemy/orm/query.py", line 1824, in <listcomp>
    _entity_descriptor(self._joinpoint_zero(), key) == value
  File "/Users/ethanhellman/Desktop/microblog/venv/lib/python3.8/site-packages/sqlalchemy/sql/operators.py", line 365, in __eq__
    return self.operate(eq, other)
  File "/Users/ethanhellman/Desktop/microblog/venv/lib/python3.8/site-packages/sqlalchemy/orm/attributes.py", line 217, in operate
    return op(self.comparator, *other, **kwargs)
  File "/Users/ethanhellman/Desktop/microblog/venv/lib/python3.8/site-packages/sqlalchemy/orm/relationships.py", line 1110, in __eq__
    self.property._optimized_compare(
  File "/Users/ethanhellman/Desktop/microblog/venv/lib/python3.8/site-packages/sqlalchemy/orm/relationships.py", line 1484, in _optimized_compare
    state = attributes.instance_state(state)
AttributeError: 'str' object has no attribute '_sa_instance_state'
2019-12-08 18:23:36,715 ERROR: Exception on /index [GET] [in /Users/ethanhellman/Desktop/microblog/venv/lib/python3.8/site-packages/flask/app.py:1890]
Traceback (most recent call last):
  File "/Users/ethanhellman/Desktop/microblog/venv/lib/python3.8/site-packages/flask/app.py", line 2446, in wsgi_app
    response = self.full_dispatch_request()
  File "/Users/ethanhellman/Desktop/microblog/venv/lib/python3.8/site-packages/flask/app.py", line 1951, in full_dispatch_request
    rv = self.handle_user_exception(e)
  File "/Users/ethanhellman/Desktop/microblog/venv/lib/python3.8/site-packages/flask/app.py", line 1820, in handle_user_exception
    reraise(exc_type, exc_value, tb)
  File "/Users/ethanhellman/Desktop/microblog/venv/lib/python3.8/site-packages/flask/_compat.py", line 39, in reraise
    raise value
  File "/Users/ethanhellman/Desktop/microblog/venv/lib/python3.8/site-packages/flask/app.py", line 1949, in full_dispatch_request
    rv = self.dispatch_request()
  File "/Users/ethanhellman/Desktop/microblog/venv/lib/python3.8/site-packages/flask/app.py", line 1935, in dispatch_request
    return self.view_functions[rule.endpoint](**req.view_args)
  File "/Users/ethanhellman/Desktop/microblog/venv/lib/python3.8/site-packages/flask_login/utils.py", line 261, in decorated_view
    return func(*args, **kwargs)
  File "/Users/ethanhellman/Desktop/microblog/app/routes.py", line 25, in index
    posts = Post.query.filter_by(user_id=self.id)
NameError: name 'self' is not defined
2019-12-08 18:23:38,651 ERROR: Exception on /index [GET] [in /Users/ethanhellman/Desktop/microblog/venv/lib/python3.8/site-packages/flask/app.py:1890]
Traceback (most recent call last):
  File "/Users/ethanhellman/Desktop/microblog/venv/lib/python3.8/site-packages/flask/app.py", line 2446, in wsgi_app
    response = self.full_dispatch_request()
  File "/Users/ethanhellman/Desktop/microblog/venv/lib/python3.8/site-packages/flask/app.py", line 1951, in full_dispatch_request
    rv = self.handle_user_exception(e)
  File "/Users/ethanhellman/Desktop/microblog/venv/lib/python3.8/site-packages/flask/app.py", line 1820, in handle_user_exception
    reraise(exc_type, exc_value, tb)
  File "/Users/ethanhellman/Desktop/microblog/venv/lib/python3.8/site-packages/flask/_compat.py", line 39, in reraise
    raise value
  File "/Users/ethanhellman/Desktop/microblog/venv/lib/python3.8/site-packages/flask/app.py", line 1949, in full_dispatch_request
    rv = self.dispatch_request()
  File "/Users/ethanhellman/Desktop/microblog/venv/lib/python3.8/site-packages/flask/app.py", line 1935, in dispatch_request
    return self.view_functions[rule.endpoint](**req.view_args)
  File "/Users/ethanhellman/Desktop/microblog/venv/lib/python3.8/site-packages/flask_login/utils.py", line 261, in decorated_view
    return func(*args, **kwargs)
  File "/Users/ethanhellman/Desktop/microblog/app/routes.py", line 25, in index
    posts = Post.query.filter_by(user_id=self.id)
NameError: name 'self' is not defined
