2019-12-08 15:42:38,736 ERROR: Exception on /edit_profile [POST] [in /Users/ethanhellman/Desktop/microblog/venv/lib/python3.8/site-packages/flask/app.py:1890]
Traceback (most recent call last):
  File "/Users/ethanhellman/Desktop/microblog/venv/lib/python3.8/site-packages/sqlalchemy/engine/base.py", line 1245, in _execute_context
    self.dialect.do_execute(
  File "/Users/ethanhellman/Desktop/microblog/venv/lib/python3.8/site-packages/sqlalchemy/engine/default.py", line 581, in do_execute
    cursor.execute(statement, parameters)
sqlite3.IntegrityError: UNIQUE constraint failed: user.username

The above exception was the direct cause of the following exception:

Traceback (most recent call last):
  File "/Users/ethanhellman/Desktop/microblog/venv/lib/python3.8/site-packages/flask/app.py", line 2446, in wsgi_app
    response = self.full_dispatch_request()
  File "/Users/ethanhellman/Desktop/microblog/venv/lib/python3.8/site-packages/flask/app.py", line 1951, in full_dispatch_request
    rv = self.handle_user_exception(e)
  File "/Users/ethanhellman/Desktop/microblog/venv/lib/python3.8/site-packages/flask/app.py", line 1820, in handle_user_exception
    reraise(exc_type, exc_value, tb)
  File "/Users/ethanhellman/Desktop/microblog/venv/lib/python3.8/site-packages/flask/_compat.py", line 39, in reraise
    raise value
  File "/Users/ethanhellman/Desktop/microblog/venv/lib/python3.8/site-packages/flask/app.py", line 1949, in full_dispatch_request
    rv = self.dispatch_request()
  File "/Users/ethanhellman/Desktop/microblog/venv/lib/python3.8/site-packages/flask/app.py", line 1935, in dispatch_request
    return self.view_functions[rule.endpoint](**req.view_args)
  File "/Users/ethanhellman/Desktop/microblog/venv/lib/python3.8/site-packages/flask_login/utils.py", line 261, in decorated_view
    return func(*args, **kwargs)
  File "/Users/ethanhellman/Desktop/microblog/app/routes.py", line 103, in edit_profile
    db.session.commit()
  File "/Users/ethanhellman/Desktop/microblog/venv/lib/python3.8/site-packages/sqlalchemy/orm/scoping.py", line 162, in do
    return getattr(self.registry(), name)(*args, **kwargs)
  File "/Users/ethanhellman/Desktop/microblog/venv/lib/python3.8/site-packages/sqlalchemy/orm/session.py", line 1027, in commit
    self.transaction.commit()
  File "/Users/ethanhellman/Desktop/microblog/venv/lib/python3.8/site-packages/sqlalchemy/orm/session.py", line 494, in commit
    self._prepare_impl()
  File "/Users/ethanhellman/Desktop/microblog/venv/lib/python3.8/site-packages/sqlalchemy/orm/session.py", line 473, in _prepare_impl
    self.session.flush()
  File "/Users/ethanhellman/Desktop/microblog/venv/lib/python3.8/site-packages/sqlalchemy/orm/session.py", line 2470, in flush
    self._flush(objects)
  File "/Users/ethanhellman/Desktop/microblog/venv/lib/python3.8/site-packages/sqlalchemy/orm/session.py", line 2608, in _flush
    transaction.rollback(_capture_exception=True)
  File "/Users/ethanhellman/Desktop/microblog/venv/lib/python3.8/site-packages/sqlalchemy/util/langhelpers.py", line 68, in __exit__
    compat.reraise(exc_type, exc_value, exc_tb)
  File "/Users/ethanhellman/Desktop/microblog/venv/lib/python3.8/site-packages/sqlalchemy/util/compat.py", line 153, in reraise
    raise value
  File "/Users/ethanhellman/Desktop/microblog/venv/lib/python3.8/site-packages/sqlalchemy/orm/session.py", line 2568, in _flush
    flush_context.execute()
  File "/Users/ethanhellman/Desktop/microblog/venv/lib/python3.8/site-packages/sqlalchemy/orm/unitofwork.py", line 422, in execute
    rec.execute(self)
  File "/Users/ethanhellman/Desktop/microblog/venv/lib/python3.8/site-packages/sqlalchemy/orm/unitofwork.py", line 586, in execute
    persistence.save_obj(
  File "/Users/ethanhellman/Desktop/microblog/venv/lib/python3.8/site-packages/sqlalchemy/orm/persistence.py", line 230, in save_obj
    _emit_update_statements(
  File "/Users/ethanhellman/Desktop/microblog/venv/lib/python3.8/site-packages/sqlalchemy/orm/persistence.py", line 995, in _emit_update_statements
    c = cached_connections[connection].execute(
  File "/Users/ethanhellman/Desktop/microblog/venv/lib/python3.8/site-packages/sqlalchemy/engine/base.py", line 982, in execute
    return meth(self, multiparams, params)
  File "/Users/ethanhellman/Desktop/microblog/venv/lib/python3.8/site-packages/sqlalchemy/sql/elements.py", line 287, in _execute_on_connection
    return connection._execute_clauseelement(self, multiparams, params)
  File "/Users/ethanhellman/Desktop/microblog/venv/lib/python3.8/site-packages/sqlalchemy/engine/base.py", line 1095, in _execute_clauseelement
    ret = self._execute_context(
  File "/Users/ethanhellman/Desktop/microblog/venv/lib/python3.8/site-packages/sqlalchemy/engine/base.py", line 1249, in _execute_context
    self._handle_dbapi_exception(
  File "/Users/ethanhellman/Desktop/microblog/venv/lib/python3.8/site-packages/sqlalchemy/engine/base.py", line 1476, in _handle_dbapi_exception
    util.raise_from_cause(sqlalchemy_exception, exc_info)
  File "/Users/ethanhellman/Desktop/microblog/venv/lib/python3.8/site-packages/sqlalchemy/util/compat.py", line 398, in raise_from_cause
    reraise(type(exception), exception, tb=exc_tb, cause=cause)
  File "/Users/ethanhellman/Desktop/microblog/venv/lib/python3.8/site-packages/sqlalchemy/util/compat.py", line 152, in reraise
    raise value.with_traceback(tb)
  File "/Users/ethanhellman/Desktop/microblog/venv/lib/python3.8/site-packages/sqlalchemy/engine/base.py", line 1245, in _execute_context
    self.dialect.do_execute(
  File "/Users/ethanhellman/Desktop/microblog/venv/lib/python3.8/site-packages/sqlalchemy/engine/default.py", line 581, in do_execute
    cursor.execute(statement, parameters)
sqlalchemy.exc.IntegrityError: (sqlite3.IntegrityError) UNIQUE constraint failed: user.username
[SQL: UPDATE user SET username=?, about_me=? WHERE user.id = ?]
[parameters: ('Ethan', 'Hello my name is Ethan Hellman, and I am learning about how to make a social media platform.', 4)]
(Background on this error at: http://sqlalche.me/e/gkpj)
2019-12-08 15:47:02,210 INFO: Microblog startup [in /Users/ethanhellman/Desktop/microblog/app/__init__.py:48]
2019-12-08 16:05:59,084 INFO: Microblog startup [in /Users/ethanhellman/Desktop/microblog/app/__init__.py:48]
2019-12-08 16:06:03,341 INFO: Microblog startup [in /Users/ethanhellman/Desktop/microblog/app/__init__.py:48]
2019-12-08 17:43:46,269 INFO: Microblog startup [in /Users/ethanhellman/Desktop/microblog/app/__init__.py:48]
2019-12-08 18:12:21,720 INFO: Microblog startup [in /Users/ethanhellman/Desktop/microblog/app/__init__.py:48]
2019-12-08 18:19:50,097 INFO: Microblog startup [in /Users/ethanhellman/Desktop/microblog/app/__init__.py:48]
2019-12-08 18:23:24,825 INFO: Microblog startup [in /Users/ethanhellman/Desktop/microblog/app/__init__.py:48]
2019-12-08 18:23:26,268 ERROR: Exception on /user/mack [GET] [in /Users/ethanhellman/Desktop/microblog/venv/lib/python3.8/site-packages/flask/app.py:1890]
Traceback (most recent call last):
  File "/Users/ethanhellman/Desktop/microblog/venv/lib/python3.8/site-packages/flask/app.py", line 2446, in wsgi_app
    response = self.full_dispatch_request()
  File "/Users/ethanhellman/Desktop/microblog/venv/lib/python3.8/site-packages/flask/app.py", line 1951, in full_dispatch_request
    rv = self.handle_user_exception(e)
  File "/Users/ethanhellman/Desktop/microblog/venv/lib/python3.8/site-packages/flask/app.py", line 1820, in handle_user_exception
    reraise(exc_type, exc_value, tb)
  File "/Users/ethanhellman/Desktop/microblog/venv/lib/python3.8/site-packages/flask/_compat.py", line 39, in reraise
    raise value
  File "/Users/ethanhellman/Desktop/microblog/venv/lib/python3.8/site-packages/flask/app.py", line 1949, in full_dispatch_request
    rv = self.dispatch_request()
  File "/Users/ethanhellman/Desktop/microblog/venv/lib/python3.8/site-packages/flask/app.py", line 1935, in dispatch_request
    return self.view_functions[rule.endpoint](**req.view_args)
  File "/Users/ethanhellman/Desktop/microblog/venv/lib/python3.8/site-packages/flask_login/utils.py", line 261, in decorated_view
    return func(*args, **kwargs)
  File "/Users/ethanhellman/Desktop/microblog/app/routes.py", line 87, in user
    posts = Post.query.filter_by(author=username).filter_by.datetime
  File "/Users/ethanhellman/Desktop/microblog/venv/lib/python3.8/site-packages/sqlalchemy/orm/query.py", line 1823, in filter_by
    clauses = [
  File "/Users/ethanhellman/Desktop/microblog/venv/lib/python3.8/site-packages/sqlalchemy/orm/query.py", line 1824, in <listcomp>
    _entity_descriptor(self._joinpoint_zero(), key) == value
  File "/Users/ethanhellman/Desktop/microblog/venv/lib/python3.8/site-packages/sqlalchemy/sql/operators.py", line 365, in __eq__
    return self.operate(eq, other)
  File "/Users/ethanhellman/Desktop/microblog/venv/lib/python3.8/site-packages/sqlalchemy/orm/attributes.py", line 217, in operate
    return op(self.comparator, *other, **kwargs)
  File "/Users/ethanhellman/Desktop/microblog/venv/lib/python3.8/site-packages/sqlalchemy/orm/relationships.py", line 1110, in __eq__
    self.property._optimized_compare(
  File "/Users/ethanhellman/Desktop/microblog/venv/lib/python3.8/site-packages/sqlalchemy/orm/relationships.py", line 1484, in _optimized_compare
    state = attributes.instance_state(state)
AttributeError: 'str' object has no attribute '_sa_instance_state'
